Workbook

Sheet Read Me
B2: ALUMINIUM STORE
B3: Pricing Framework — v1.0
B4: A Specialised Operating Division of Besbpo Group · September 2026
B6: Overview
B7: This workbook prices all 2,147 SKUs in the Master Product Catalogue using a cost-basis engine: a Base Cost is built up from real physical inputs (aluminium weight, glass area, finish, hardware) on the Priced Catalogue sheet, then marked up per the Category Markup Bands and split into Retail / Trade / Volume tiers. Every price is a live formula — change an assumption on the Cost Assumptions or Markup Bands sheet and the full catalogue recalculates.
B9: How Base Cost is built
B10: Dimensioned finished products (windows, doors, skylights, garage doors, awnings, louvres, pergolas, carports, balcony/Juliet balustrades): Base Cost = opening area × a fully-loaded Area Rate for that product sub-category (frame, standard glazing/infill, and fabrication already included), plus a glazing upgrade differential where the line specifies IGU or another premium glazing over that product's baseline, plus a flat per-unit hardware allowance. The Area Rates are calibrated against real 2026 SA market pricing for equivalent products (see the Competitive Benchmark sheet) rather than built up from raw aluminium weight — an early first-principles version of this model, costed purely from profile weight and glass area, understated real finished-window and door pricing by roughly three times once checked against the market, because it missed the die, hardware, and fabrication value a finished system actually carries.
B11: Balustrade runs: Base Cost = length × (post/rail material cost, from aluminium weight/m and finish) + length × an infill rate that varies by type (glass, flat-bar, cable, or picket).
B12: Raw extrusion stock: priced on weight (length × profile kg/m × aluminium R/kg) plus finish — no fabrication loading and a thin resale margin, since this line sells to other fabricators as a near-commodity input rather than as a finished product.
B13: Non-dimensioned lines (shopfronts, curtain walling, partitioning, fascias/gutters, hardware, glass rate-card, sealants, fixings): Base Cost is a direct market-rate input (shown in blue), the same way the Area Rates and aluminium R/kg figures are inputs — these are still genuine costs, just not derived from a parsed dimension.
B15: Key assumptions (all illustrative — validate before going live)
B16: Aluminium cost: R18.5/kg — derived from an FOB South African mill-finish window/door profile quote of roughly US$1,050-1,200/tonne, converted at ~R16.40/USD. LME aluminium plus billet premium moves; re-check before relying on this for a live quote.
... B29: Priced Catalogue — all 2,147 SKUs with Base Cost, Markup %, and Retail/Trade/Volume price, live via formula.

Sheet Cost Assumptions
B1: COST ASSUMPTIONS
B2: Global Inputs
B3: Aluminium Cost (R/kg) | C3: 18.5
B4: Fabrication & Labour Loading (%) | C4: 0.32
B5: Flat-Bar / Panel Infill Rate (R/m²) | C5: 450
B7: Frame Weight per Linear Metre (kg/m) — extrusion stock & balustrade posts only
B8: WINDOW | C8: 1.7
B9: DOOR | C9: 2.3
B10: LIGHT | C10: 1.1
B11: STRUCTURAL | C11: 2.6
B12: BALUSTRADE | C12: 1.4
B15: Finish Cost per Linear Metre (R/m) — extrusion stock & balustrade posts only
B16: Natural Anodised | C16: 25
B17: Satin White (RAL 9016) | C17: 38
B18: Charcoal Grey (RAL 7016) | C18: 38
B19: Graphite Black (RAL 9005) | C19: 40
B20: Bronze Anodised | C20: 55
B23: Fully-Loaded Area Rate (R/m²) — windows, doors, pergolas/carports, screens, skylights, garage doors, balcony
B24: Sliding Windows | C24: 2300
B25: Casement Windows | C25: 2100
B26: Awning Windows | C26: 2150
B27: Hopper Windows | C27: 2000
B28: Louvre Windows | C28: 2400
B29: Fixed / Picture Windows | C29: 1750
B30: Tilt & Turn Windows | C30: 2800
B31: Bay & Bow Window Units | C31: 2600
B32: Sliding Doors | C32: 2050
B33: Stacking & Folding Doors | C33: 3200
B34: Hinged / Casement Doors | C34: 2300
B35: French Doors | C35: 2400
... B44: Balcony & Juliet Balustrades | C44: 1900
B47: Glazing Upgrade over Baseline (R/m²) — windows & doors only
B48: Standard Single-Glazed (4mm Clear Float) | C48: 0
B49: IGU Double-Glazed (4-12Ar-4 Low-E) | C49: 550
B50: 6.38mm Laminated Safety | C50: 0
B51: IGU Double-Glazed Laminated (6.38-12Ar-4 Low-E) | C51: 700
B52: 4mm Clear Float | C52: 0
B53: 6mm Toughened Louvre Blade | C53: 0
B54: Aluminium Louvre Blade | C54: 0
B55: Stainless Security Mesh | C55: 0
...

Sheet Category Markup Bands
A1: Category | B1: Sub-Category (override, if any) | C1: Markup %
A2: Windows | B2: — (applies to all sub-categories) | C2: 0.42
A3: Doors | B3: — (applies to all sub-categories) | C3: 0.4
A4: Facade & Structural Systems | B4: — (applies to all sub-categories) | C4: 0.3
A5: Outdoor Living & Shading | B5: — (applies to all sub-categories) | C5: 0.45
A6: Railing & Screening Systems | B6: — (applies to all sub-categories) | C6: 0.42
A7: Roofing Glazing & Garage Doors | B7: — (applies to all sub-categories) | C7: 0.38
A8: Raw Material & Hardware
A9: Raw Material & Hardware | B9: Extrusion Profiles & Raw Stock | C9: 0.18
A10: Raw Material & Hardware | B10: Hardware & Ironmongery | C10: 0.48
A11: Raw Material & Hardware | B11: Glazing & Glass | C11: 0.25
A12: Raw Material & Hardware | B12: Sealants, Gaskets & Weatherproofing | C12: 0.55
A13: Raw Material & Hardware | B13: Fixings, Fasteners & Brackets | C13: 0.55

Sheet Customer Tiers
A1: Tier | B1: Discount off Retail
A2: Retail (List Price) | B2: 0
A3: Trade | B3: 0.12
A4: Volume | B4: 0.2
A6: Trade tier: registered installers, builders, and fabricators buying on account.
A7: Volume tier: developer/contractor project quantities and CMI Partner Network project work.

Sheet Delivery & Additional Charges
A1: Charge | B1: Rate
A2: Local delivery — within 30km of nearest yard/branch (standard goods, up to 1,000kg) | B2: 850
A3: Local delivery — within 30km, 1,000–3,000kg | B3: 1150
A4: Local delivery — above 3,000kg or beyond 30km | B4: Quote individually
A5: Fragile-goods handling surcharge — glazed units, curtain-wall/shopfront panels (% of order value) | B5: 0.08
A6: Oversized/abnormal load permit — case-by-case (long extrusion runs, large structural members) | B6: Quote individually
A7: Made-to-Order lead time — standard finish, standard glazing | B7: Quote individually
A8: Made-to-Order lead time — CMI Partner Network (curtain walling, large facade packages) | B8: Quote individually
A10: Delivery banding follows the same weight-based, distance-banded model standing as policy on Roofsteel; the fragile-goods surcharge is new for glazed product.

Sheet Competitive Benchmark
A1: Product Line | B1: SA Market Range (2026) | C1: Aluminium Store Retail (comparable size) | D1: Source / Note
A2: Standard sliding window (1209×909mm) | B2: R2,500 – R6,000 | C2: ='Priced Catalogue'!R22 -> 3944.2719 | D2: Van Acht (Gauteng/North West/Western Cape installer), 2026 published guide pricing
A3: Casement window (1209×1209mm) | B3: R3,000 – R7,000 | C3: ='Priced Catalogue'!R272 -> 4713.7327 | D3: Van Acht, 2026 published guide pricing
A4: Custom/large window (2409×1509mm fixed) | B4: R8,000 – R20,000+ | C4: ='Priced Catalogue'!R646 -> 9388.4248 | D4: Van Acht, 2026 published guide pricing
A5: Standard sliding door (1809×2090mm) | B5: R8,000 – R15,000 | C5: ='Priced Catalogue'!R784 -> 11620.925 | D5: Van Acht, 2026 published guide pricing
A6: Stacking/folding door (3-leaf, 3609×2090mm) | B6: R25,000 – R60,000+ | C6: ='Priced Catalogue'!R1024 -> 34561.789 | D6: Van Acht, 2026 published guide pricing
A7: Standard framed pivot door (1509×2700mm) — see note | B7: R40,000 – R100,000+ (frameless, not this line) | C7: ='Priced Catalogue'!R1310 -> 20734.07 | D7: Van Acht cites this range for fully frameless structural-glass entrance systems — a different product to the standard framed Pivot Door priced alongside it here. A directly comparable frameless system would be quoted through Curtain Walling / Structural Glazing (per m²), not this catalogue line.
A9: Comparable-size cell references point at specific rows in the Priced Catalogue; re-check the row references if the catalogue is re-sorted or re-filtered.

Sheet Priced Catalogue
A1: SKU | B1: Category | C1: Sub-Category | D1: Product Name | E1: Configuration | F1: Standard Size | G1: Finish | H1: Glazing / Material Spec | I1: Unit of Sale | J1: Segment(s) Served | K1: Fulfilment Type | L1: Frame Class | M1: Width (mm) | N1: Height (mm) | O1: Length (m) | P1: Base Cost (R) | Q1: Markup % | R1: Retail (R) | S1: Trade (R) | T1: Volume (R)
A2: ALS-SLW-0001 | B2: Windows | C2: Sliding Windows | D2: Aluminium Sliding Window — 2-Pane Slider (1 Fixed + 1 Sliding) — 609x609mm — Natural Anodised — Standard Single-Glazed (4mm Clear Float) | E2: 2-Pane Slider (1 Fixed + 1 Sliding) | F2: 609x609mm | G2: Natural Anodised | H2: Standard Single-Glazed (4mm Clear Float) | I2: Each | J2: Residential/Commercial | K2: Stock | L2: WINDOW | M2: 609 | N2: 609 | P2: =(M2*N2/1000000)*(INDEX(AreaRate_Vals,MATCH(C2,AreaRate_Keys,0))+IFERROR(INDEX(GlazingUpg_Vals,MATCH(H2,GlazingUpg_Keys,0)),0))+INDEX(Hardware_Vals,MATCH("Windows",Hardware_Keys,0)) -> 1103.0263 | Q2: =INDEX(Markup_Vals,MATCH("Windows",MarkupCat_Keys,0)) -> 0.42 | R2: =P2*(1+Q2) -> 1566.2973 | S2: =R2*(1-TradeDiscount) -> 1378.3417 | T2: =R2*(1-VolumeDiscount) -> 1253.0379
A3: ALS-SLW-0002 | B3: Windows | C3: Sliding Windows | D3: Aluminium Sliding Window — 2-Pane Slider (1 Fixed + 1 Sliding) — 609x609mm — Satin White (RAL 9016) — Standard Single-Glazed (4mm Clear Float) | E3: 2-Pane Slider (1 Fixed + 1 Sliding) | F3: 609x609mm | G3: Satin White (RAL 9016) | H3: Standard Single-Glazed (4mm Clear Float) | I3: Each | J3: Residential/Commercial | K3: Stock | L3: WINDOW | M3: 609 | N3: 609 | P3: =(M3*N3/1000000)*(INDEX(AreaRate_Vals,MATCH(C3,AreaRate_Keys,0))+IFERROR(INDEX(GlazingUpg_Vals,MATCH(H3,GlazingUpg_Keys,0)),0))+INDEX(Hardware_Vals,MATCH("Windows",Hardware_Keys,0)) -> 1103.0263 | Q3: =INDEX(Markup_Vals,MATCH("Windows",MarkupCat_Keys,0)) -> 0.42 | R3: =P3*(1+Q3) -> 1566.2973 | S3: =R3*(1-TradeDiscount) -> 1378.3417 | T3: =R3*(1-VolumeDiscount) -> 1253.0379
A4: ALS-SLW-0003 | B4: Windows | C4: Sliding Windows | D4: Aluminium Sliding Window — 2-Pane Slider (1 Fixed + 1 Sliding) — 609x609mm — Charcoal Grey (RAL 7016) — Standard Single-Glazed (4mm Clear Float) | E4: 2-Pane Slider (1 Fixed + 1 Sliding) | F4: 609x609mm | G4: Charcoal Grey (RAL 7016) | H4: Standard Single-Glazed (4mm Clear Float) | I4: Each | J4: Residential/Commercial | K4: Stock | L4: WINDOW | M4: 609 | N4: 609 | P4: =(M4*N4/1000000)*(INDEX(AreaRate_Vals,MATCH(C4,AreaRate_Keys,0))+IFERROR(INDEX(GlazingUpg_Vals,MATCH(H4,GlazingUpg_Keys,0)),0))+INDEX(Hardware_Vals,MATCH("Windows",Hardware_Keys,0)) -> 1103.0263 | Q4: =INDEX(Markup_Vals,MATCH("Windows",MarkupCat_Keys,0)) -> 0.42 | R4: =P4*(1+Q4) -> 1566.2973 | S4: =R4*(1-TradeDiscount) -> 1378.3417 | T4: =R4*(1-VolumeDiscount) -> 1253.0379
A5: ALS-SLW-0004 | B5: Windows | C5: Sliding Windows | D5: Aluminium Sliding Window — 2-Pane Slider (1 Fixed + 1 Sliding) — 609x609mm — Bronze Anodised — Standard Single-Glazed (4mm Clear Float) | E5: 2-Pane Slider (1 Fixed + 1 Sliding) | F5: 609x609mm | G5: Bronze Anodised | H5: Standard Single-Glazed (4mm Clear Float) | I5: Each | J5: Residential/Commercial | K5: Stock | L5: WINDOW | M5: 609 | N5: 609 | P5: =(M5*N5/1000000)*(INDEX(AreaRate_Vals,MATCH(C5,AreaRate_Keys,0))+IFERROR(INDEX(GlazingUpg_Vals,MATCH(H5,GlazingUpg_Keys,0)),0))+INDEX(Hardware_Vals,MATCH("Windows",Hardware_Keys,0)) -> 1103.0263 | Q5: =INDEX(Markup_Vals,MATCH("Windows",MarkupCat_Keys,0)) -> 0.42 | R5: =P5*(1+Q5) -> 1566.2973 | S5: =R5*(1-TradeDiscount) -> 1378.3417 | T5: =R5*(1-VolumeDiscount) -> 1253.0379
A6: ALS-SLW-0005 | B6: Windows | C6: Sliding Windows | D6: Aluminium Sliding Window — 2-Pane Slider (1 Fixed + 1 Sliding) — 609x609mm — Graphite Black (RAL 9005) — Standard Single-Glazed (4mm Clear Float) | E6: 2-Pane Slider (1 Fixed + 1 Sliding) | F6: 609x609mm | G6: Graphite Black (RAL 9005) | H6: Standard Single-Glazed (4mm Clear Float) | I6: Each | J6: Residential/Commercial | K6: Stock | L6: WINDOW | M6: 609 | N6: 609 | P6: =(M6*N6/1000000)*(INDEX(AreaRate_Vals,MATCH(C6,AreaRate_Keys,0))+IFERROR(INDEX(GlazingUpg_Vals,MATCH(H6,GlazingUpg_Keys,0)),0))+INDEX(Hardware_Vals,MATCH("Windows",Hardware_Keys,0)) -> 1103.0263 | Q6: =INDEX(Markup_Vals,MATCH("Windows",MarkupCat_Keys,0)) -> 0.42 | R6: =P6*(1+Q6) -> 1566.2973 | S6: =R6*(1-TradeDiscount) -> 1378.3417 | T6: =R6*(1-VolumeDiscount) -> 1253.0379
A7: ALS-SLW-0006 | B7: Windows | C7: Sliding Windows | D7: Aluminium Sliding Window — 2-Pane Slider (1 Fixed + 1 Sliding) — 609x609mm — Natural Anodised — IGU Double-Glazed (4-12Ar-4 Low-E) | E7: 2-Pane Slider (1 Fixed + 1 Sliding) | F7: 609x609mm | G7: Natural Anodised | H7: IGU Double-Glazed (4-12Ar-4 Low-E) | I7: Each | J7: Residential/Commercial | K7: Stock | L7: WINDOW | M7: 609 | N7: 609 | P7: =(M7*N7/1000000)*(INDEX(AreaRate_Vals,MATCH(C7,AreaRate_Keys,0))+IFERROR(INDEX(GlazingUpg_Vals,MATCH(H7,GlazingUpg_Keys,0)),0))+INDEX(Hardware_Vals,MATCH("Windows",Hardware_Keys,0)) -> 1307.0108 | Q7: =INDEX(Markup_Vals,MATCH("Windows",MarkupCat_Keys,0)) -> 0.42 | R7: =P7*(1+Q7) -> 1855.9554 | S7: =R7*(1-TradeDiscount) -> 1633.2408 | T7: =R7*(1-VolumeDiscount) -> 1484.7643
A8: ALS-SLW-0007 | B8: Windows | C8: Sliding Windows | D8: Aluminium Sliding Window — 2-Pane Slider (1 Fixed + 1 Sliding) — 609x609mm — Satin White (RAL 9016) — IGU Double-Glazed (4-12Ar-4 Low-E) | E8: 2-Pane Slider (1 Fixed + 1 Sliding) | F8: 609x609mm | G8: Satin White (RAL 9016) | H8: IGU Double-Glazed (4-12Ar-4 Low-E) | I8: Each | J8: Residential/Commercial | K8: Stock | L8: WINDOW | M8: 609 | N8: 609 | P8: =(M8*N8/1000000)*(INDEX(AreaRate_Vals,MATCH(C8,AreaRate_Keys,0))+IFERROR(INDEX(GlazingUpg_Vals,MATCH(H8,GlazingUpg_Keys,0)),0))+INDEX(Hardware_Vals,MATCH("Windows",Hardware_Keys,0)) -> 1307.0108 | Q8: =INDEX(Markup_Vals,MATCH("Windows",MarkupCat_Keys,0)) -> 0.42 | R8: =P8*(1+Q8) -> 1855.9554 | S8: =R8*(1-TradeDiscount) -> 1633.2408 | T8: =R8*(1-VolumeDiscount) -> 1484.7643
A9: ALS-SLW-0008 | B9: Windows | C9: Sliding Windows | D9: Aluminium Sliding Window — 2-Pane Slider (1 Fixed + 1 Sliding) — 609x609mm — Charcoal Grey (RAL 7016) — IGU Double-Glazed (4-12Ar-4 Low-E) | E9: 2-Pane Slider (1 Fixed + 1 Sliding) | F9: 609x609mm | G9: Charcoal Grey (RAL 7016) | H9: IGU Double-Glazed (4-12Ar-4 Low-E) | I9: Each | J9: Residential/Commercial | K9: Stock | L9: WINDOW | M9: 609 | N9: 609 | P9: =(M9*N9/1000000)*(INDEX(AreaRate_Vals,MATCH(C9,AreaRate_Keys,0))+IFERROR(INDEX(GlazingUpg_Vals,MATCH(H9,GlazingUpg_Keys,0)),0))+INDEX(Hardware_Vals,MATCH("Windows",Hardware_Keys,0)) -> 1307.0108 | Q9: =INDEX(Markup_Vals,MATCH("Windows",MarkupCat_Keys,0)) -> 0.42 | R9: =P9*(1+Q9) -> 1855.9554 | S9: =R9*(1-TradeDiscount) -> 1633.2408 | T9: =R9*(1-VolumeDiscount) -> 1484.7643
A10: ALS-SLW-0009 | B10: Windows | C10: Sliding Windows | D10: Aluminium Sliding Window — 2-Pane Slider (1 Fixed + 1 Sliding) — 609x609mm — Bronze Anodised — IGU Double-Glazed (4-12Ar-4 Low-E) | E10: 2-Pane Slider (1 Fixed + 1 Sliding) | F10: 609x609mm | G10: Bronze Anodised | H10: IGU Double-Glazed (4-12Ar-4 Low-E) | I10: Each | J10: Residential/Commercial | K10: Stock | L10: WINDOW | M10: 609 | N10: 609 | P10: =(M10*N10/1000000)*(INDEX(AreaRate_Vals,MATCH(C10,AreaRate_Keys,0))+IFERROR(INDEX(GlazingUpg_Vals,MATCH(H10,GlazingUpg_Keys,0)),0))+INDEX(Hardware_Vals,MATCH("Windows",Hardware_Keys,0)) -> 1307.0108 | Q10: =INDEX(Markup_Vals,MATCH("Windows",MarkupCat_Keys,0)) -> 0.42 | R10: =P10*(1+Q10) -> 1855.9554 | S10: =R10*(1-TradeDiscount) -> 1633.2408 | T10: =R10*(1-VolumeDiscount) -> 1484.7643
A11: ALS-SLW-0010 | B11: Windows | C11: Sliding Windows | D11: Aluminium Sliding Window — 2-Pane Slider (1 Fixed + 1 Sliding) — 609x609mm — Graphite Black (RAL 9005) — IGU Double-Glazed (4-12Ar-4 Low-E) | E11: 2-Pane Slider (1 Fixed + 1 Sliding) | F11: 609x609mm | G11: Graphite Black (RAL 9005) | H11: IGU Double-Glazed (4-12Ar-4 Low-E) | I11: Each | J11: Residential/Commercial | K11: Stock | L11: WINDOW | M11: 609 | N11: 609 | P11: =(M11*N11/1000000)*(INDEX(AreaRate_Vals,MATCH(C11,AreaRate_Keys,0))+IFERROR(INDEX(GlazingUpg_Vals,MATCH(H11,GlazingUpg_Keys,0)),0))+INDEX(Hardware_Vals,MATCH("Windows",Hardware_Keys,0)) -> 1307.0108 | Q11: =INDEX(Markup_Vals,MATCH("Windows",MarkupCat_Keys,0)) -> 0.42 | R11: =P11*(1+Q11) -> 1855.9554 | S11: =R11*(1-TradeDiscount) -> 1633.2408 | T11: =R11*(1-VolumeDiscount) -> 1484.7643
A12: ALS-SLW-0011 | B12: Windows | C12: Sliding Windows | D12: Aluminium Sliding Window — 2-Pane Slider (1 Fixed + 1 Sliding) — 1209x609mm — Natural Anodised — Standard Single-Glazed (4mm Clear Float) | E12: 2-Pane Slider (1 Fixed + 1 Sliding) | F12: 1209x609mm | G12: Natural Anodised | H12: Standard Single-Glazed (4mm Clear Float) | I12: Each | J12: Residential/Commercial | K12: Stock | L12: WINDOW | M12: 1209 | N12: 609 | P12: =(M12*N12/1000000)*(INDEX(AreaRate_Vals,MATCH(C12,AreaRate_Keys,0))+IFERROR(INDEX(GlazingUpg_Vals,MATCH(H12,GlazingUpg_Keys,0)),0))+INDEX(Hardware_Vals,MATCH("Windows",Hardware_Keys,0)) -> 1943.4463 | Q12: =INDEX(Markup_Vals,MATCH("Windows",MarkupCat_Keys,0)) -> 0.42 | R12: =P12*(1+Q12) -> 2759.6937 | S12: =R12*(1-TradeDiscount) -> 2428.5305 | T12: =R12*(1-VolumeDiscount) -> 2207.755
A13: ALS-SLW-0012 | B13: Windows | C13: Sliding Windows | D13: Aluminium Sliding Window — 2-Pane Slider (1 Fixed + 1 Sliding) — 1209x609mm — Satin White (RAL 9016) — Standard Single-Glazed (4mm Clear Float) | E13: 2-Pane Slider (1 Fixed + 1 Sliding) | F13: 1209x609mm | G13: Satin White (RAL 9016) | H13: Standard Single-Glazed (4mm Clear Float) | I13: Each | J13: Residential/Commercial | K13: Stock | L13: WINDOW | M13: 1209 | N13: 609 | P13: =(M13*N13/1000000)*(INDEX(AreaRate_Vals,MATCH(C13,AreaRate_Keys,0))+IFERROR(INDEX(GlazingUpg_Vals,MATCH(H13,GlazingUpg_Keys,0)),0))+INDEX(Hardware_Vals,MATCH("Windows",Hardware_Keys,0)) -> 1943.4463 | Q13: =INDEX(Markup_Vals,MATCH("Windows",MarkupCat_Keys,0)) -> 0.42 | R13: =P13*(1+Q13) -> 2759.6937 | S13: =R13*(1-TradeDiscount) -> 2428.5305 | T13: =R13*(1-VolumeDiscount) -> 2207.755
... A763: ALS-BBW-0048 | B763: Windows | C763: Bay & Bow Window Units | D763: Aluminium Box Bay (90° Square) Window Unit — 3009x1809mm — Bronze Anodised | E763: Box Bay (90° Square) | F763: 3009x1809mm | G763: Bronze Anodised | H763: 4mm Clear Float | I763: Each | J763: Residential | K763: Made-to-Order | L763: WINDOW | M763: 3009 | N763: 1809 | P763: =(M763*N763/1000000)*(INDEX(AreaRate_Vals,MATCH(C763,AreaRate_Keys,0))+IFERROR(INDEX(GlazingUpg_Vals,MATCH(H763,GlazingUpg_Keys,0)),0))+INDEX(Hardware_Vals,MATCH("Windows",Hardware_Keys,0)) -> 14402.531 | Q763: =INDEX(Markup_Vals,MATCH("Windows",MarkupCat_Keys,0)) -> 0.42 | R763: =P763*(1+Q763) -> 20451.593 | S763: =R763*(1-TradeDiscount) -> 17997.402 | T763: =R763*(1-VolumeDiscount) -> 16361.275
A764: ALS-SLD-0001 | B764: Doors | C764: Sliding Doors | D764: Aluminium Sliding Door — 2-Panel Slider (1 Fixed + 1 Sliding) — 1809x2009mm — Natural Anodised — 6.38mm Laminated Safety | E764: 2-Panel Slider (1 Fixed + 1 Sliding) | F764: 1809x2009mm | G764: Natural Anodised | H764: 6.38mm Laminated Safety | I764: Each | J764: Residential/Commercial | K764: Stock | L764: DOOR | M764: 1809 | N764: 2009 | P764: =(M764*N764/1000000)*(INDEX(AreaRate_Vals,MATCH(C764,AreaRate_Keys,0))+IFERROR(INDEX(GlazingUpg_Vals,MATCH(H764,GlazingUpg_Keys,0)),0))+INDEX(Hardware_Vals,MATCH("Doors",Hardware_Keys,0)) -> 8000.2761 | Q764: =INDEX(Markup_Vals,MATCH("Doors",MarkupCat_Keys,0)) -> 0.4 | R764: =P764*(1+Q764) -> 11200.386 | S764: =R764*(1-TradeDiscount) -> 9856.3401 | T764: =R764*(1-VolumeDiscount) -> 8960.3092
A765: ALS-SLD-0002 | B765: Doors | C765: Sliding Doors | D765: Aluminium Sliding Door — 2-Panel Slider (1 Fixed + 1 Sliding) — 1809x2009mm — Satin White (RAL 9016) — 6.38mm Laminated Safety | E765: 2-Panel Slider (1 Fixed + 1 Sliding) | F765: 1809x2009mm | G765: Satin White (RAL 9016) | H765: 6.38mm Laminated Safety | I765: Each | J765: Residential/Commercial | K765: Stock | L765: DOOR | M765: 1809 | N765: 2009 | P765: =(M765*N765/1000000)*(INDEX(AreaRate_Vals,MATCH(C765,AreaRate_Keys,0))+IFERROR(INDEX(GlazingUpg_Vals,MATCH(H765,GlazingUpg_Keys,0)),0))+INDEX(Hardware_Vals,MATCH("Doors",Hardware_Keys,0)) -> 8000.2761 | Q765: =INDEX(Markup_Vals,MATCH("Doors",MarkupCat_Keys,0)) -> 0.4 | R765: =P765*(1+Q765) -> 11200.386 | S765: =R765*(1-TradeDiscount) -> 9856.3401 | T765: =R765*(1-VolumeDiscount) -> 8960.3092
A766: ALS-SLD-0003 | B766: Doors | C766: Sliding Doors | D766: Aluminium Sliding Door — 2-Panel Slider (1 Fixed + 1 Sliding) — 1809x2009mm — Charcoal Grey (RAL 7016) — 6.38mm Laminated Safety | E766: 2-Panel Slider (1 Fixed + 1 Sliding) | F766: 1809x2009mm | G766: Charcoal Grey (RAL 7016) | H766: 6.38mm Laminated Safety | I766: Each | J766: Residential/Commercial | K766: Stock | L766: DOOR | M766: 1809 | N766: 2009 | P766: =(M766*N766/1000000)*(INDEX(AreaRate_Vals,MATCH(C766,AreaRate_Keys,0))+IFERROR(INDEX(GlazingUpg_Vals,MATCH(H766,GlazingUpg_Keys,0)),0))+INDEX(Hardware_Vals,MATCH("Doors",Hardware_Keys,0)) -> 8000.2761 | Q766: =INDEX(Markup_Vals,MATCH("Doors",MarkupCat_Keys,0)) -> 0.4 | R766: =P766*(1+Q766) -> 11200.386 | S766: =R766*(1-TradeDiscount) -> 9856.3401 | T766: =R766*(1-VolumeDiscount) -> 8960.3092
A767: ALS-SLD-0004 | B767: Doors | C767: Sliding Doors | D767: Aluminium Sliding Door — 2-Panel Slider (1 Fixed + 1 Sliding) — 1809x2009mm — Bronze Anodised — 6.38mm Laminated Safety | E767: 2-Panel Slider (1 Fixed + 1 Sliding) | F767: 1809x2009mm | G767: Bronze Anodised | H767: 6.38mm Laminated Safety | I767: Each | J767: Residential/Commercial | K767: Stock | L767: DOOR | M767: 1809 | N767: 2009 | P767: =(M767*N767/1000000)*(INDEX(AreaRate_Vals,MATCH(C767,AreaRate_Keys,0))+IFERROR(INDEX(GlazingUpg_Vals,MATCH(H767,GlazingUpg_Keys,0)),0))+INDEX(Hardware_Vals,MATCH("Doors",Hardware_Keys,0)) -> 8000.2761 | Q767: =INDEX(Markup_Vals,MATCH("Doors",MarkupCat_Keys,0)) -> 0.4 | R767: =P767*(1+Q767) -> 11200.386 | S767: =R767*(1-TradeDiscount) -> 9856.3401 | T767: =R767*(1-VolumeDiscount) -> 8960.3092
A768: ALS-SLD-0005 | B768: Doors | C768: Sliding Doors | D768: Aluminium Sliding Door — 2-Panel Slider (1 Fixed + 1 Sliding) — 1809x2009mm — Graphite Black (RAL 9005) — 6.38mm Laminated Safety | E768: 2-Panel Slider (1 Fixed + 1 Sliding) | F768: 1809x2009mm | G768: Graphite Black (RAL 9005) | H768: 6.38mm Laminated Safety | I768: Each | J768: Residential/Commercial | K768: Stock | L768: DOOR | M768: 1809 | N768: 2009 | P768: =(M768*N768/1000000)*(INDEX(AreaRate_Vals,MATCH(C768,AreaRate_Keys,0))+IFERROR(INDEX(GlazingUpg_Vals,MATCH(H768,GlazingUpg_Keys,0)),0))+INDEX(Hardware_Vals,MATCH("Doors",Hardware_Keys,0)) -> 8000.2761 | Q768: =INDEX(Markup_Vals,MATCH("Doors",MarkupCat_Keys,0)) -> 0.4 | R768: =P768*(1+Q768) -> 11200.386 | S768: =R768*(1-TradeDiscount) -> 9856.3401 | T768: =R768*(1-VolumeDiscount) -> 8960.3092
A769: ALS-SLD-0006 | B769: Doors | C769: Sliding Doors | D769: Aluminium Sliding Door — 2-Panel Slider (1 Fixed + 1 Sliding) — 1809x2009mm — Natural Anodised — IGU Double-Glazed Laminated (6.38-12Ar-4 Low-E) | E769: 2-Panel Slider (1 Fixed + 1 Sliding) | F769: 1809x2009mm | G769: Natural Anodised | H769: IGU Double-Glazed Laminated (6.38-12Ar-4 Low-E) | I769: Each | J769: Residential/Commercial | K769: Stock | L769: DOOR | M769: 1809 | N769: 2009 | P769: =(M769*N769/1000000)*(INDEX(AreaRate_Vals,MATCH(C769,AreaRate_Keys,0))+IFERROR(INDEX(GlazingUpg_Vals,MATCH(H769,GlazingUpg_Keys,0)),0))+INDEX(Hardware_Vals,MATCH("Doors",Hardware_Keys,0)) -> 10544.273 | Q769: =INDEX(Markup_Vals,MATCH("Doors",MarkupCat_Keys,0)) -> 0.4 | R769: =P769*(1+Q769) -> 14761.982 | S769: =R769*(1-TradeDiscount) -> 12990.544 | T769: =R769*(1-VolumeDiscount) -> 11809.585
A770: ALS-SLD-0007 | B770: Doors | C770: Sliding Doors | D770: Aluminium Sliding Door — 2-Panel Slider (1 Fixed + 1 Sliding) — 1809x2009mm — Satin White (RAL 9016) — IGU Double-Glazed Laminated (6.38-12Ar-4 Low-E) | E770: 2-Panel Slider (1 Fixed + 1 Sliding) | F770: 1809x2009mm | G770: Satin White (RAL 9016) | H770: IGU Double-Glazed Laminated (6.38-12Ar-4 Low-E) | I770: Each | J770: Residential/Commercial | K770: Stock | L770: DOOR | M770: 1809 | N770: 2009 | P770: =(M770*N770/1000000)*(INDEX(AreaRate_Vals,MATCH(C770,AreaRate_Keys,0))+IFERROR(INDEX(GlazingUpg_Vals,MATCH(H770,GlazingUpg_Keys,0)),0))+INDEX(Hardware_Vals,MATCH("Doors",Hardware_Keys,0)) -> 10544.273 | Q770: =INDEX(Markup_Vals,MATCH("Doors",MarkupCat_Keys,0)) -> 0.4 | R770: =P770*(1+Q770) -> 14761.982 | S770: =R770*(1-TradeDiscount) -> 12990.544 | T770: =R770*(1-VolumeDiscount) -> 11809.585
A771: ALS-SLD-0008 | B771: Doors | C771: Sliding Doors | D771: Aluminium Sliding Door — 2-Panel Slider (1 Fixed + 1 Sliding) — 1809x2009mm — Charcoal Grey (RAL 7016) — IGU Double-Glazed Laminated (6.38-12Ar-4 Low-E) | E771: 2-Panel Slider (1 Fixed + 1 Sliding) | F771: 1809x2009mm | G771: Charcoal Grey (RAL 7016) | H771: IGU Double-Glazed Laminated (6.38-12Ar-4 Low-E) | I771: Each | J771: Residential/Commercial | K771: Stock | L771: DOOR | M771: 1809 | N771: 2009 | P771: =(M771*N771/1000000)*(INDEX(AreaRate_Vals,MATCH(C771,AreaRate_Keys,0))+IFERROR(INDEX(GlazingUpg_Vals,MATCH(H771,GlazingUpg_Keys,0)),0))+INDEX(Hardware_Vals,MATCH("Doors",Hardware_Keys,0)) -> 10544.273 | Q771: =INDEX(Markup_Vals,MATCH("Doors",MarkupCat_Keys,0)) -> 0.4 | R771: =P771*(1+Q771) -> 14761.982 | S771: =R771*(1-TradeDiscount) -> 12990.544 | T771: =R771*(1-VolumeDiscount) -> 11809.585
A772: ALS-SLD-0009 | B772: Doors | C772: Sliding Doors | D772: Aluminium Sliding Door — 2-Panel Slider (1 Fixed + 1 Sliding) — 1809x2009mm — Bronze Anodised — IGU Double-Glazed Laminated (6.38-12Ar-4 Low-E) | E772: 2-Panel Slider (1 Fixed + 1 Sliding) | F772: 1809x2009mm | G772: Bronze Anodised | H772: IGU Double-Glazed Laminated (6.38-12Ar-4 Low-E) | I772: Each | J772: Residential/Commercial | K772: Stock | L772: DOOR | M772: 1809 | N772: 2009 | P772: =(M772*N772/1000000)*(INDEX(AreaRate_Vals,MATCH(C772,AreaRate_Keys,0))+IFERROR(INDEX(GlazingUpg_Vals,MATCH(H772,GlazingUpg_Keys,0)),0))+INDEX(Hardware_Vals,MATCH("Doors",Hardware_Keys,0)) -> 10544.273 | Q772: =INDEX(Markup_Vals,MATCH("Doors",MarkupCat_Keys,0)) -> 0.4 | R772: =P772*(1+Q772) -> 14761.982 | S772: =R772*(1-TradeDiscount) -> 12990.544 | T772: =R772*(1-VolumeDiscount) -> 11809.585
A773: ALS-SLD-0010 | B773: Doors | C773: Sliding Doors | D773: Aluminium Sliding Door — 2-Panel Slider (1 Fixed + 1 Sliding) — 1809x2009mm — Graphite Black (RAL 9005) — IGU Double-Glazed Laminated (6.38-12Ar-4 Low-E) | E773: 2-Panel Slider (1 Fixed + 1 Sliding) | F773: 1809x2009mm | G773: Graphite Black (RAL 9005) | H773: IGU Double-Glazed Laminated (6.38-12Ar-4 Low-E) | I773: Each | J773: Residential/Commercial | K773: Stock | L773: DOOR | M773: 1809 | N773: 2009 | P773: =(M773*N773/1000000)*(INDEX(AreaRate_Vals,MATCH(C773,AreaRate_Keys,0))+IFERROR(INDEX(GlazingUpg_Vals,MATCH(H773,GlazingUpg_Keys,0)),0))+INDEX(Hardware_Vals,MATCH("Doors",Hardware_Keys,0)) -> 10544.273 | Q773: =INDEX(Markup_Vals,MATCH("Doors",MarkupCat_Keys,0)) -> 0.4 | R773: =P773*(1+Q773) -> 14761.982 | S773: =R773*(1-TradeDiscount) -> 12990.544 | T773: =R773*(1-VolumeDiscount) -> 11809.585
A774: ALS-SLD-0011 | B774: Doors | C774: Sliding Doors | D774: Aluminium Sliding Door — 2-Panel Slider (1 Fixed + 1 Sliding) — 2409x2009mm — Natural Anodised — 6.38mm Laminated Safety | E774: 2-Panel Slider (1 Fixed + 1 Sliding) | F774: 2409x2009mm | G774: Natural Anodised | H774: 6.38mm Laminated Safety | I774: Each | J774: Residential/Commercial | K774: Stock | L774: DOOR | M774: 2409 | N774: 2009 | P774: =(M774*N774/1000000)*(INDEX(AreaRate_Vals,MATCH(C774,AreaRate_Keys,0))+IFERROR(INDEX(GlazingUpg_Vals,MATCH(H774,GlazingUpg_Keys,0)),0))+INDEX(Hardware_Vals,MATCH("Doors",Hardware_Keys,0)) -> 10471.346 | Q774: =INDEX(Markup_Vals,MATCH("Doors",MarkupCat_Keys,0)) -> 0.4 | R774: =P774*(1+Q774) -> 14659.884 | S774: =R774*(1-TradeDiscount) -> 12900.698 | T774: =R774*(1-VolumeDiscount) -> 11727.908
A775: ALS-SLD-0012 | B775: Doors | C775: Sliding Doors | D775: Aluminium Sliding Door — 2-Panel Slider (1 Fixed + 1 Sliding) — 2409x2009mm — Satin White (RAL 9016) — 6.38mm Laminated Safety | E775: 2-Panel Slider (1 Fixed + 1 Sliding) | F775: 2409x2009mm | G775: Satin White (RAL 9016) | H775: 6.38mm Laminated Safety | I775: Each | J775: Residential/Commercial | K775: Stock | L775: DOOR | M775: 2409 | N775: 2009 | P775: =(M775*N775/1000000)*(INDEX(AreaRate_Vals,MATCH(C775,AreaRate_Keys,0))+IFERROR(INDEX(GlazingUpg_Vals,MATCH(H775,GlazingUpg_Keys,0)),0))+INDEX(Hardware_Vals,MATCH("Doors",Hardware_Keys,0)) -> 10471.346 | Q775: =INDEX(Markup_Vals,MATCH("Doors",MarkupCat_Keys,0)) -> 0.4 | R775: =P775*(1+Q775) -> 14659.884 | S775: =R775*(1-TradeDiscount) -> 12900.698 | T775: =R775*(1-VolumeDiscount) -> 11727.908
... A1313: ALS-PVD-0020 | B1313: Doors | C1313: Pivot Doors | D1313: Aluminium Pivot Entrance Door — 1509x2700mm — Bronze Anodised | E1313: Offset-Pivot, Oversized Entrance | F1313: 1509x2700mm | G1313: Bronze Anodised | H1313: 6.38mm Laminated Safety | I1313: Each | J1313: Commercial/Residential | K1313: Made-to-Order | L1313: DOOR | M1313: 1509 | N1313: 2700 | P1313: =(M1313*N1313/1000000)*(INDEX(AreaRate_Vals,MATCH(C1313,AreaRate_Keys,0))+IFERROR(INDEX(GlazingUpg_Vals,MATCH(H1313,GlazingUpg_Keys,0)),0))+INDEX(Hardware_Vals,MATCH("Doors",Hardware_Keys,0)) -> 14810.05 | Q1313: =INDEX(Markup_Vals,MATCH("Doors",MarkupCat_Keys,0)) -> 0.4 | R1313: =P1313*(1+Q1313) -> 20734.07 | S1313: =R1313*(1-TradeDiscount) -> 18245.982 | T1313: =R1313*(1-VolumeDiscount) -> 16587.256
A1314: ALS-SCD-0001 | B1314: Doors | C1314: Security & Screen Doors | D1314: Aluminium Sliding Security Door (Mesh Infill) — 809x2009mm — Natural Anodised | E1314: Sliding Security Door (Mesh Infill) | F1314: 809x2009mm | G1314: Natural Anodised | H1314: Stainless Security Mesh | I1314: Each | J1314: Residential/Commercial | K1314: Stock | L1314: DOOR | M1314: 809 | N1314: 2009 | P1314: =(M1314*N1314/1000000)*INDEX(AreaRate_Vals,MATCH(C1314,AreaRate_Keys,0))+INDEX(Hardware_Vals,MATCH("Doors",Hardware_Keys,0)) -> 2825.3934 | Q1314: =INDEX(Markup_Vals,MATCH("Doors",MarkupCat_Keys,0)) -> 0.4 | R1314: =P1314*(1+Q1314) -> 3955.5508 | S1314: =R1314*(1-TradeDiscount) -> 3480.8847 | T1314: =R1314*(1-VolumeDiscount) -> 3164.4406
A1315: ALS-SCD-0002 | B1315: Doors | C1315: Security & Screen Doors | D1315: Aluminium Sliding Security Door (Mesh Infill) — 809x2009mm — Satin White (RAL 9016) | E1315: Sliding Security Door (Mesh Infill) | F1315: 809x2009mm | G1315: Satin White (RAL 9016) | H1315: Stainless Security Mesh | I1315: Each | J1315: Residential/Commercial | K1315: Stock | L1315: DOOR | M1315: 809 | N1315: 2009 | P1315: =(M1315*N1315/1000000)*INDEX(AreaRate_Vals,MATCH(C1315,AreaRate_Keys,0))+INDEX(Hardware_Vals,MATCH("Doors",Hardware_Keys,0)) -> 2825.3934 | Q1315: =INDEX(Markup_Vals,MATCH("Doors",MarkupCat_Keys,0)) -> 0.4 | R1315: =P1315*(1+Q1315) -> 3955.5508 | S1315: =R1315*(1-TradeDiscount) -> 3480.8847 | T1315: =R1315*(1-VolumeDiscount) -> 3164.4406
A1316: ALS-SCD-0003 | B1316: Doors | C1316: Security & Screen Doors | D1316: Aluminium Sliding Security Door (Mesh Infill) — 809x2009mm — Charcoal Grey (RAL 7016) | E1316: Sliding Security Door (Mesh Infill) | F1316: 809x2009mm | G1316: Charcoal Grey (RAL 7016) | H1316: Stainless Security Mesh | I1316: Each | J1316: Residential/Commercial | K1316: Stock | L1316: DOOR | M1316: 809 | N1316: 2009 | P1316: =(M1316*N1316/1000000)*INDEX(AreaRate_Vals,MATCH(C1316,AreaRate_Keys,0))+INDEX(Hardware_Vals,MATCH("Doors",Hardware_Keys,0)) -> 2825.3934 | Q1316: =INDEX(Markup_Vals,MATCH("Doors",MarkupCat_Keys,0)) -> 0.4 | R1316: =P1316*(1+Q1316) -> 3955.5508 | S1316: =R1316*(1-TradeDiscount) -> 3480.8847 | T1316: =R1316*(1-VolumeDiscount) -> 3164.4406
A1317: ALS-SCD-0004 | B1317: Doors | C1317: Security & Screen Doors | D1317: Aluminium Sliding Security Door (Mesh Infill) — 909x2009mm — Natural Anodised | E1317: Sliding Security Door (Mesh Infill) | F1317: 909x2009mm | G1317: Natural Anodised | H1317: Stainless Security Mesh | I1317: Each | J1317: Residential/Commercial | K1317: Stock | L1317: DOOR | M1317: 909 | N1317: 2009 | P1317: =(M1317*N1317/1000000)*INDEX(AreaRate_Vals,MATCH(C1317,AreaRate_Keys,0))+INDEX(Hardware_Vals,MATCH("Doors",Hardware_Keys,0)) -> 3106.6534 | Q1317: =INDEX(Markup_Vals,MATCH("Doors",MarkupCat_Keys,0)) -> 0.4 | R1317: =P1317*(1+Q1317) -> 4349.3148 | S1317: =R1317*(1-TradeDiscount) -> 3827.397 | T1317: =R1317*(1-VolumeDiscount) -> 3479.4518
A1318: ALS-SCD-0005 | B1318: Doors | C1318: Security & Screen Doors | D1318: Aluminium Sliding Security Door (Mesh Infill) — 909x2009mm — Satin White (RAL 9016) | E1318: Sliding Security Door (Mesh Infill) | F1318: 909x2009mm | G1318: Satin White (RAL 9016) | H1318: Stainless Security Mesh | I1318: Each | J1318: Residential/Commercial | K1318: Stock | L1318: DOOR | M1318: 909 | N1318: 2009 | P1318: =(M1318*N1318/1000000)*INDEX(AreaRate_Vals,MATCH(C1318,AreaRate_Keys,0))+INDEX(Hardware_Vals,MATCH("Doors",Hardware_Keys,0)) -> 3106.6534 | Q1318: =INDEX(Markup_Vals,MATCH("Doors",MarkupCat_Keys,0)) -> 0.4 | R1318: =P1318*(1+Q1318) -> 4349.3148 | S1318: =R1318*(1-TradeDiscount) -> 3827.397 | T1318: =R1318*(1-VolumeDiscount) -> 3479.4518
A1319: ALS-SCD-0006 | B1319: Doors | C1319: Security & Screen Doors | D1319: Aluminium Sliding Security Door (Mesh Infill) — 909x2009mm — Charcoal Grey (RAL 7016) | E1319: Sliding Security Door (Mesh Infill) | F1319: 909x2009mm | G1319: Charcoal Grey (RAL 7016) | H1319: Stainless Security Mesh | I1319: Each | J1319: Residential/Commercial | K1319: Stock | L1319: DOOR | M1319: 909 | N1319: 2009 | P1319: =(M1319*N1319/1000000)*INDEX(AreaRate_Vals,MATCH(C1319,AreaRate_Keys,0))+INDEX(Hardware_Vals,MATCH("Doors",Hardware_Keys,0)) -> 3106.6534 | Q1319: =INDEX(Markup_Vals,MATCH("Doors",MarkupCat_Keys,0)) -> 0.4 | R1319: =P1319*(1+Q1319) -> 4349.3148 | S1319: =R1319*(1-TradeDiscount) -> 3827.397 | T1319: =R1319*(1-VolumeDiscount) -> 3479.4518
A1320: ALS-SCD-0007 | B1320: Doors | C1320: Security & Screen Doors | D1320: Aluminium Sliding Security Door (Mesh Infill) — 1209x2009mm — Natural Anodised | E1320: Sliding Security Door (Mesh Infill) | F1320: 1209x2009mm | G1320: Natural Anodised | H1320: Stainless Security Mesh | I1320: Each | J1320: Residential/Commercial | K1320: Stock | L1320: DOOR | M1320: 1209 | N1320: 2009 | P1320: =(M1320*N1320/1000000)*INDEX(AreaRate_Vals,MATCH(C1320,AreaRate_Keys,0))+INDEX(Hardware_Vals,MATCH("Doors",Hardware_Keys,0)) -> 3950.4334 | Q1320: =INDEX(Markup_Vals,MATCH("Doors",MarkupCat_Keys,0)) -> 0.4 | R1320: =P1320*(1+Q1320) -> 5530.6068 | S1320: =R1320*(1-TradeDiscount) -> 4866.9339 | T1320: =R1320*(1-VolumeDiscount) -> 4424.4854
A1321: ALS-SCD-0008 | B1321: Doors | C1321: Security & Screen Doors | D1321: Aluminium Sliding Security Door (Mesh Infill) — 1209x2009mm — Satin White (RAL 9016) | E1321: Sliding Security Door (Mesh Infill) | F1321: 1209x2009mm | G1321: Satin White (RAL 9016) | H1321: Stainless Security Mesh | I1321: Each | J1321: Residential/Commercial | K1321: Stock | L1321: DOOR | M1321: 1209 | N1321: 2009 | P1321: =(M1321*N1321/1000000)*INDEX(AreaRate_Vals,MATCH(C1321,AreaRate_Keys,0))+INDEX(Hardware_Vals,MATCH("Doors",Hardware_Keys,0)) -> 3950.4334 | Q1321: =INDEX(Markup_Vals,MATCH("Doors",MarkupCat_Keys,0)) -> 0.4 | R1321: =P1321*(1+Q1321) -> 5530.6068 | S1321: =R1321*(1-TradeDiscount) -> 4866.9339 | T1321: =R1321*(1-VolumeDiscount) -> 4424.4854
A1322: ALS-SCD-0009 | B1322: Doors | C1322: Security & Screen Doors | D1322: Aluminium Sliding Security Door (Mesh Infill) — 1209x2009mm — Charcoal Grey (RAL 7016) | E1322: Sliding Security Door (Mesh Infill) | F1322: 1209x2009mm | G1322: Charcoal Grey (RAL 7016) | H1322: Stainless Security Mesh | I1322: Each | J1322: Residential/Commercial | K1322: Stock | L1322: DOOR | M1322: 1209 | N1322: 2009 | P1322: =(M1322*N1322/1000000)*INDEX(AreaRate_Vals,MATCH(C1322,AreaRate_Keys,0))+INDEX(Hardware_Vals,MATCH("Doors",Hardware_Keys,0)) -> 3950.4334 | Q1322: =INDEX(Markup_Vals,MATCH("Doors",MarkupCat_Keys,0)) -> 0.4 | R1322: =P1322*(1+Q1322) -> 5530.6068 | S1322: =R1322*(1-TradeDiscount) -> 4866.9339 | T1322: =R1322*(1-VolumeDiscount) -> 4424.4854
A1323: ALS-SCD-0010 | B1323: Doors | C1323: Security & Screen Doors | D1323: Aluminium Sliding Security Door (Mesh Infill) — 1809x2009mm — Natural Anodised | E1323: Sliding Security Door (Mesh Infill) | F1323: 1809x2009mm | G1323: Natural Anodised | H1323: Stainless Security Mesh | I1323: Each | J1323: Residential/Commercial | K1323: Stock | L1323: DOOR | M1323: 1809 | N1323: 2009 | P1323: =(M1323*N1323/1000000)*INDEX(AreaRate_Vals,MATCH(C1323,AreaRate_Keys,0))+INDEX(Hardware_Vals,MATCH("Doors",Hardware_Keys,0)) -> 5637.9934 | Q1323: =INDEX(Markup_Vals,MATCH("Doors",MarkupCat_Keys,0)) -> 0.4 | R1323: =P1323*(1+Q1323) -> 7893.1908 | S1323: =R1323*(1-TradeDiscount) -> 6946.0079 | T1323: =R1323*(1-VolumeDiscount) -> 6314.5526
A1324: ALS-SCD-0011 | B1324: Doors | C1324: Security & Screen Doors | D1324: Aluminium Sliding Security Door (Mesh Infill) — 1809x2009mm — Satin White (RAL 9016) | E1324: Sliding Security Door (Mesh Infill) | F1324: 1809x2009mm | G1324: Satin White (RAL 9016) | H1324: Stainless Security Mesh | I1324: Each | J1324: Residential/Commercial | K1324: Stock | L1324: DOOR | M1324: 1809 | N1324: 2009 | P1324: =(M1324*N1324/1000000)*INDEX(AreaRate_Vals,MATCH(C1324,AreaRate_Keys,0))+INDEX(Hardware_Vals,MATCH("Doors",Hardware_Keys,0)) -> 5637.9934 | Q1324: =INDEX(Markup_Vals,MATCH("Doors",MarkupCat_Keys,0)) -> 0.4 | R1324: =P1324*(1+Q1324) -> 7893.1908 | S1324: =R1324*(1-TradeDiscount) -> 6946.0079 | T1324: =R1324*(1-VolumeDiscount) -> 6314.5526
A1325: ALS-SCD-0012 | B1325: Doors | C1325: Security & Screen Doors | D1325: Aluminium Sliding Security Door (Mesh Infill) — 1809x2009mm — Charcoal Grey (RAL 7016) | E1325: Sliding Security Door (Mesh Infill) | F1325: 1809x2009mm | G1325: Charcoal Grey (RAL 7016) | H1325: Stainless Security Mesh | I1325: Each | J1325: Residential/Commercial | K1325: Stock | L1325: DOOR | M1325: 1809 | N1325: 2009 | P1325: =(M1325*N1325/1000000)*INDEX(AreaRate_Vals,MATCH(C1325,AreaRate_Keys,0))+INDEX(Hardware_Vals,MATCH("Doors",Hardware_Keys,0)) -> 5637.9934 | Q1325: =INDEX(Markup_Vals,MATCH("Doors",MarkupCat_Keys,0)) -> 0.4 | R1325: =P1325*(1+Q1325) -> 7893.1908 | S1325: =R1325*(1-TradeDiscount) -> 6946.0079 | T1325: =R1325*(1-VolumeDiscount) -> 6314.5526
... A1367: ALS-SCD-0054 | B1367: Doors | C1367: Security & Screen Doors | D1367: Aluminium Retractable Security Screen Door — 3009x2009mm — Charcoal Grey (RAL 7016) | E1367: Retractable Security Screen Door | F1367: 3009x2009mm | G1367: Charcoal Grey (RAL 7016) | H1367: Stainless Security Mesh | I1367: Each | J1367: Residential/Commercial | K1367: Stock | L1367: DOOR | M1367: 3009 | N1367: 2009 | P1367: =(M1367*N1367/1000000)*INDEX(AreaRate_Vals,MATCH(C1367,AreaRate_Keys,0))+INDEX(Hardware_Vals,MATCH("Doors",Hardware_Keys,0)) -> 9013.1134 | Q1367: =INDEX(Markup_Vals,MATCH("Doors",MarkupCat_Keys,0)) -> 0.4 | R1367: =P1367*(1+Q1367) -> 12618.359 | S1367: =R1367*(1-TradeDiscount) -> 11104.156 | T1367: =R1367*(1-VolumeDiscount) -> 10094.687
...
